Workbook

Sheet 说明
A1: 条目 | B1: 内容
A2: 目标 | B2: 《怪物猎人:旅人》手机→PC端的功能差异清单与工作量评估。范围:输入与操控、快捷键显示、界面UIUX、画面与性能
A3: 对照组 | B3: A:旅人(手机)↔荒野(PC);B:鸣潮(手机)↔鸣潮(PC);补充:原神/星铁/绝区零端手同服、崛起掌机→PC、Steam Deck与Xbox掌机规范
A4: 使用方式 | B4: 主表=「全量清单」,按大类/子类/优先级筛选;工作量改动只改K~O列或「假设参数」,汇总自动重算
A5: 估算口径 | B5: 单位人天;首版实现(不含多轮迭代);假设客户端已有UI框架但未做PC适配;汇总页含风险系数
A6: 角色 | B6: 策划/交互 | UI美术 | 客户端程序 | TA/引擎 | QA
A7: 复杂度 | B7: S<3人天 | M 3~10 | L 10~30 | XL >30
A8: 蓝色数字 | B8: 「假设参数」中的蓝色数字为可调输入,修改后相关行与汇总自动变化
A9: 冲突1 | B9: 鸣潮闪避/跳跃:NTGame记闪避=空格;百度知道记跳跃=空格、闪避=Shift
A10: 冲突2 | B10: 鸣潮切换角色:1/2/3 vs F1~F4,疑为版本差异
A11: 冲突3 | B11: 鸣潮钩索:鼠标中键 vs Tab
A12: 冲突4 | B12: 荒野集中弱点攻击/救难信号/投射器发射仍待确认
A13: 最大不确定性 | B13: ①旅人引擎与现有输入/UI框架状态 ②实际界面数量 ③武器数量 ④是否上Steam(决定Steam Deck/Steam Input相关项)

Sheet PCfeatureLsit
A1: 特性需求 | E1: 需求描述 | F1: 对照与标记(绿=本次新增,蓝=本次改写为通用检查清单)
A3: Feature Team Scope | B3: Super-Epic | C3: Epic | D3: Summary | F3: 对照全量清单编号 | G3: 本次标记 | H3: 备注
A4: Cross相关 | B4: 场景资产 | C4: 场景资产迁移 | D4: 地形cross,并确保打包正常 | E4: 让打包后的PC和手机内存和内容能够完全隔离 | F4: 4.3.6
D5: PCG Cross,并确保打包正常 | F5: 4.3.6
D6: 贴花cross,并确保打包正常 | F6: 4.3.6
C7: 配置检查 | D7: 内容隔离后的资产管理规则设计 | F7: 4.3.6
B8: PC灯光 | C8: 场景灯光相关 | D8: 场景Cross,并确保打包正常 （关卡、资产、材质） | F8: 4.1.3
C9: 配置检查 | D9: 检查PC灯光配置与手机端隔离,PC端独立光照质量档位 | F9: 4.1.3
B10: 角色资产 | C10: 角色模型资产迁移 | D10: 角色高精度模型/LOD/贴图迁移至PC包,与手机包隔离 | F10: 4.1.2
C11: 配置刷新 | D11: 刷新角色资产平台配置(LOD、材质质量档) | F11: 4.1.2
B12: 动画资产 | C12: 动画资产迁移 | D12: 动画资产迁移PC;验证120/144帧下动画插值、判定与表现 | F12: 4.2.4
C13: 配置刷新 | D13: 刷新动画压缩、采样率等平台配置
B14: 特效资产 | C14: 特效资产迁移 | D14: 特效资产迁移PC,按画质档分级 | F14: 4.1.2
C15: 相关配置刷新 | D15: 刷新特效LOD、粒子数量上限等平台配置 | F15: 4.1.2
B16: 剧情过场 | C16: CutScene | D16: 过场高码率/高分辨率输出,超宽屏黑边与HUD处理 | F16: 4.3.7,4.3.8
C17: sequence | D17: 实时过场sequence在高帧率/超宽屏下的相机与表现校验 | F17: 4.3.7
C18: PCGDialogue剧情 | D18: 对话推进/自动/跳过/回看的键鼠手柄快捷键与提示 | F18: 2.2.6
B19: 工具需求 | C19: Cross资产迁移工具 | D19: 批量迁移、平台标记与PC/手机资产差异比对工具
C20: 策划配置检查工具 | D20: 检查PC/手机配置隔离、按键绑定与按键提示配置的完整性
A21: 基建支持 | B21: 引擎相关 | D21: PC输入API、窗口/显示模式、着色器预编译、超分/帧生成、低延迟等引擎侧支持 | F21: 1.1.5,3.1.5,4.2.5,4.1.5,4.2.2
C22: 光线追踪 | D22: 可选光追 | F22: 4.1.6
C23: 菜单/后台限帧 | D23: 菜单与后台降帧 | F23: 4.2.6
B24: 美术相关 | D24: UI与图标资源高清化;Xbox/DualSense/键鼠三套按键图标资源 | F24: 3.1.8,2.4.2
B25: 性能专项 | C25: 性能Benchmark | D25: 3060 | F25: 4.3.1,4.3.5
C26: 内存/显存/流式加载 | D26: 资源分包、占用监控、流式加载 | F26: 4.3.2
C27: 长时运行稳定性 | D27: 显存泄漏/性能漂移 | F27: 4.3.3
B28: 环境交互专项 | D28: 滑索/弹射器/鼓风机等建造交互的键鼠手柄输入与提示 | F28: 1.2.6,2.2.2
B29: 数据与稳定性 | C29: 数据埋点 | D29: 输入设备占比(键鼠/手柄)、PC硬件分布、帧率性能、改键与设置项选择率 | G29: 新增 | H29: 用于后续调整默认键位与画质档位
C30: 崩溃上报与配置检测 | D30: 崩溃文件收集、显卡驱动版本检测、低于最低配置时提示 | G30: 新增
A31: 端手功能 体验差异 | B31: 通用 | C31: 快捷键显示逻辑 | D31: 在主界面、交互界面、系统界面等合适的地方显示各类快捷键的ICON | E31: 特殊需求，11月PC展示视频相关 | F31: 2.1.1,2.1.2,2.2.1,2.2.3,2.3.2
C32: 3C操作提示 | D32: 在主界面常驻显示当前可以执行的角色3D操作功能键 | E32: 特殊需求，11月PC展示视频相关 | F32: 2.1.1,3.2.1
C33: 键鼠/手柄 | D33: 键盘鼠标快捷键自适应切换显示 | F33: 1.1.2,2.4.1,2.4.4
C34: 快捷键自定义功能 | D34: 键鼠+手柄改键界面、冲突检测、恢复默认、分设备保存 | F34: 1.5.1,1.5.4,1.5.5
C35: 输入设备谱系 | D35: 确定PC端设备矩阵:键鼠+Xbox/DualSense/第三方手柄,是否含陀螺仪/震动 | F35: 1.1.1
C36: 多显示器/串流下设备判定 | D36: 输入设备与显示设备解耦,避免串流/多屏误判 | F36: 1.1.3
C37: 手柄型号识别 | D37: 按VID/PID识别Xbox/DualSense/Switch Pro,未知手柄回退Xbox图标 | F37: 1.1.4
C38: PC触屏设备(触屏笔记本/二合一) | D38: 决定PC端是否保留触屏UI作为第三输入模式 | F38: 1.1.7
C39: 连段同键提示 | D39: 明确同一键连按的提示 | F39: 2.1.3
C40: 提示随改键实时更新 | D40: 提示读取当前绑定动态生成,禁止写死贴图 | F40: 2.1.4
C41: 弹窗确认/取消提示 | D41: 所有弹窗键帽提示 | F41: 2.2.5
...

Sheet 工作量汇总
A1: 一、按大类 × 角色(人天)
A2: 大类 | B2: 条目数 | C2: 策划/交互 | D2: UI美术 | E2: 客户端 | F2: TA/引擎 | G2: QA | H2: 合计
A3: 1-输入与操控 | B3: =COUNTIF(全量清单!$B$2:$B$131,$A3) | C3: =SUMIFS(全量清单!$K$2:$K$131,全量清单!$B$2:$B$131,$A3) | D3: =SUMIFS(全量清单!$L$2:$L$131,全量清单!$B$2:$B$131,$A3) | E3: =SUMIFS(全量清单!$M$2:$M$131,全量清单!$B$2:$B$131,$A3) | F3: =SUMIFS(全量清单!$N$2:$N$131,全量清单!$B$2:$B$131,$A3) | G3: =SUMIFS(全量清单!$O$2:$O$131,全量清单!$B$2:$B$131,$A3) | H3: =SUM(C3:G3)
A4: 2-快捷键显示 | B4: =COUNTIF(全量清单!$B$2:$B$131,$A4) | C4: =SUMIFS(全量清单!$K$2:$K$131,全量清单!$B$2:$B$131,$A4) | D4: =SUMIFS(全量清单!$L$2:$L$131,全量清单!$B$2:$B$131,$A4) | E4: =SUMIFS(全量清单!$M$2:$M$131,全量清单!$B$2:$B$131,$A4) | F4: =SUMIFS(全量清单!$N$2:$N$131,全量清单!$B$2:$B$131,$A4) | G4: =SUMIFS(全量清单!$O$2:$O$131,全量清单!$B$2:$B$131,$A4) | H4: =SUM(C4:G4)
A5: 3-界面UIUX | B5: =COUNTIF(全量清单!$B$2:$B$131,$A5) | C5: =SUMIFS(全量清单!$K$2:$K$131,全量清单!$B$2:$B$131,$A5) | D5: =SUMIFS(全量清单!$L$2:$L$131,全量清单!$B$2:$B$131,$A5) | E5: =SUMIFS(全量清单!$M$2:$M$131,全量清单!$B$2:$B$131,$A5) | F5: =SUMIFS(全量清单!$N$2:$N$131,全量清单!$B$2:$B$131,$A5) | G5: =SUMIFS(全量清单!$O$2:$O$131,全量清单!$B$2:$B$131,$A5) | H5: =SUM(C5:G5)
A6: 4-画面与性能 | B6: =COUNTIF(全量清单!$B$2:$B$131,$A6) | C6: =SUMIFS(全量清单!$K$2:$K$131,全量清单!$B$2:$B$131,$A6) | D6: =SUMIFS(全量清单!$L$2:$L$131,全量清单!$B$2:$B$131,$A6) | E6: =SUMIFS(全量清单!$M$2:$M$131,全量清单!$B$2:$B$131,$A6) | F6: =SUMIFS(全量清单!$N$2:$N$131,全量清单!$B$2:$B$131,$A6) | G6: =SUMIFS(全量清单!$O$2:$O$131,全量清单!$B$2:$B$131,$A6) | H6: =SUM(C6:G6)
A7: 小计 | B7: =SUM(B3:B6) | C7: =SUM(C3:C6) | D7: =SUM(D3:D6) | E7: =SUM(E3:E6) | F7: =SUM(F3:F6) | G7: =SUM(G3:G6) | H7: =SUM(H3:H6)
A8: ×风险系数 | C8: =C7*假设参数!$B$12 | D8: =D7*假设参数!$B$12 | E8: =E7*假设参数!$B$12 | F8: =F7*假设参数!$B$12 | G8: =G7*假设参数!$B$12 | H8: =H7*假设参数!$B$12
A9: 折合人月 | C9: =C8/假设参数!$B$13 | D9: =D8/假设参数!$B$13 | E9: =E8/假设参数!$B$13 | F9: =F8/假设参数!$B$13 | G9: =G8/假设参数!$B$13 | H9: =H8/假设参数!$B$13
A11: 二、按优先级(人天)
A12: 优先级 | B12: 条目数 | C12: 合计人天 | D12: ×风险系数 | E12: 折合人月 | F12: 说明
A13: P0 | B13: =COUNTIF(全量清单!$I$2:$I$131,A13) | C13: =SUMIFS(全量清单!$P$2:$P$131,全量清单!$I$2:$I$131,A13) | D13: =C13*假设参数!$B$12 | E13: =D13/假设参数!$B$13 | F13: 地基与上线必需:输入抽象层、热切换、图标体系、ESC/光标、HUD提示、焦点导航、帧率与兼容
A14: P1 | B14: =COUNTIF(全量清单!$I$2:$I$131,A14) | C14: =SUMIFS(全量清单!$P$2:$P$131,全量清单!$I$2:$I$131,A14) | D14: =C14*假设参数!$B$12 | E14: =D14/假设参数!$B$13 | F14: 体验关键:界面快捷键规范、鼠标态、大屏重排、改键辅助、画质细项
A15: P2 | B15: =COUNTIF(全量清单!$I$2:$I$131,A15) | C15: =SUMIFS(全量清单!$P$2:$P$131,全量清单!$I$2:$I$131,A15) | D15: =C15*假设参数!$B$12 | E15: =D15/假设参数!$B$13 | F15: 增强项:光追/DLSS、HDR、手柄高级特性、批量/拖拽、键位云同步

Sheet 假设参数
A1: 参数 | B1: 数值 | C1: 说明
A2: 需适配的系统/交互界面数量(个) | B2: 60 | C2: 待内部盘点旅人实际界面数后替换
A3: 手柄焦点导航·单界面客户端人天 | B3: 0.5 | C3: 含焦点顺序、焦点记忆、快捷键位
A4: 手柄焦点导航·单界面QA人天 | B4: 0.15
A5: 鼠标态适配·单界面客户端人天 | B5: 0.25 | C5: 悬停、tooltip、滚轮、右键返回
A6: 快捷键提示接入·单界面UI人天 | B6: 0.15 | C6: 底部操作提示栏排版
A7: 快捷键提示接入·单界面客户端人天 | B7: 0.2 | C7: 绑定读取与刷新
A8: 大屏重排·单界面UI人天 | B8: 0.5 | C8: 仅对需重排的界面,按全部界面粗估
A9: 大屏重排·单界面客户端人天 | B9: 0.3
A10: 武器/角色数量(需出键位方案) | B10: 8 | C10: 旅人实际武器数待确认
A11: 单武器键位方案·策划人天 | B11: 1 | C11: 含键鼠+手柄两套
A12: 风险系数(联调/返工/沟通) | B12: 1.3 | C12: 估算区间约 ±30%
A13: 每人月工作日 | B13: 22

Sheet 全量清单
A1: 编号 | B1: 大类 | C1: 子类 | D1: 功能差异点 | E1: 移动端现状 | F1: PC端参考做法 | G1: 旅人PC需做的适配 | H1: 参考来源 | I1: 优先级 | J1: 复杂度 | K1: 策划/交互 | L1: UI美术 | M1: 客户端 | N1: TA/引擎 | O1: QA | P1: 合计人天 | Q1: 状态 | R1: 备注
A2: 1.1.1 | B2: 1-输入与操控 | C2: 1.1 设备与底层 | D2: 输入设备谱系 | E2: 旅人:纯触屏(虚拟摇杆+按键);鸣潮手机:触屏+可接蓝牙手柄 | F2: 荒野:键鼠+手柄双轨;鸣潮PC:键鼠为主可切手柄,PS5 DualSense适配 | G2: 确定PC端设备矩阵:键鼠+Xbox/DualSense/第三方手柄,是否含陀螺仪/震动 | H2: S6,S1 | I2: P0 | J2: S | K2: 2 | L2: 0 | M2: 1 | N2: 0 | O2: 1 | P2: =SUM(K2:O2) | Q2: 待评审
A3: 1.1.2 | B3: 1-输入与操控 | C3: 1.1 设备与底层 | D3: 键鼠/手柄热切换 | E3: 无 | F3: 鸣潮PC:全局无缝键鼠↔手柄热切换,动一下设备即切对应界面 | G3: 任意I/O输入即激活对应设备并切换整套提示 | H3: S9,S6 | I3: P0 | J3: M | K3: 2 | L3: 0 | M3: 8 | N3: 0 | O3: 4 | P3: =SUM(K3:O3) | Q3: 待评审
A4: 1.1.3 | B4: 1-输入与操控 | C4: 1.1 设备与底层 | D4: 多显示器/串流下设备判定 | E4: 无 | F4: 鸣潮PC:显示设备切换智能判定 | G4: 输入设备与显示设备解耦,避免串流/多屏误判 | H4: S10 | I4: P2 | J4: M | K4: 1 | L4: 0 | M4: 4 | N4: 0 | O4: 3 | P4: =SUM(K4:O4) | Q4: 待评审
A5: 1.1.4 | B5: 1-输入与操控 | C5: 1.1 设备与底层 | D5: 手柄型号识别 | E5: 手机蓝牙手柄常被识别为Xbox | F5: 鸣潮:识别后自动切换图标;DS4Windows伪装时显示Xbox图标 | G5: 按VID/PID识别Xbox/DualSense/Switch Pro,未知手柄回退Xbox图标 | H5: S22 | I5: P0 | J5: M | K5: 1 | L5: 0 | M5: 5 | N5: 0 | O5: 4 | P5: =SUM(K5:O5) | Q5: 待评审
A6: 1.1.5 | B6: 1-输入与操控 | C6: 1.1 设备与底层 | D6: PC输入API接入 | E6: 手机触屏事件 | F6: Xbox推荐GameInput API;Steam Deck推荐Steam Input API | G6: 选型并接入PC输入API(含DualSense原生支持) | H6: S17,S18 | I6: P0 | J6: L | K6: 1 | L6: 0 | M6: 12 | N6: 0 | O6: 4 | P6: =SUM(K6:O6) | Q6: 待评审 | R6: 引擎现状未知,可能已有部分支持
A7: 1.1.6 | B7: 1-输入与操控 | C7: 1.1 设备与底层 | D7: 输入抽象层(Action Mapping)重构 | E7: 触屏按钮直接绑定逻辑 | F7: 荒野/鸣潮:动作→多设备绑定,可重映射 | G7: 触屏按钮→抽象Action→键鼠/手柄/触屏多绑定;是改键、提示、热切换的地基 | H7: S3,S6,EXP | I7: P0 | J7: XL | K7: 5 | L7: 0 | M7: 25 | N7: 0 | O7: 6 | P7: =SUM(K7:O7) | Q7: 待评审 | R7: 工作量最大的底层项
A8: 1.1.7 | B8: 1-输入与操控 | C8: 1.1 设备与底层 | D8: PC触屏设备(触屏笔记本/二合一) | E8: 触屏原生 | F8: Xbox掌机指南:建议保留原生触控 | G8: 决定PC端是否保留触屏UI作为第三输入模式 | H8: S18 | I8: P2 | J8: M | K8: 1 | L8: 1 | M8: 4 | N8: 0 | O8: 2 | P8: =SUM(K8:O8) | Q8: 待评审
A9: 1.2.1 | B9: 1-输入与操控 | C9: 1.2 默认键位映射 | D9: 普通攻击 | E9: 旅人:点按=轻击、长按=重击 | F9: 荒野:△=鼠标左键;鸣潮PC:左键连点连段、长按重击 | G9: 确认点按/长按的键鼠等价表达 | H9: S2,S3,S6 | I9: P0 | J9: S | K9: 1 | L9: 0 | M9: 1 | N9: 0 | O9: 1 | P9: =SUM(K9:O9) | Q9: 待评审
A10: 1.2.2 | B10: 1-输入与操控 | C10: 1.2 默认键位映射 | D10: 技能攻击 | E10: 旅人:3个技能键(核心输出/环境交互/爆发) | F10: 荒野:○=右键;鸣潮PC:E技能/R解放/T回声 | G10: 3技能键映射到独立键位 | H10: S2,S6 | I10: P0 | J10: S | K10: 1 | L10: 0 | M10: 1 | N10: 0 | O10: 1 | P10: =SUM(K10:O10) | Q10: 待评审
A11: 1.2.3 | B11: 1-输入与操控 | C11: 1.2 默认键位映射 | D11: 闪避/受身 | E11: 旅人:闪避键,被打飞后可触发受身 | F11: 荒野:✕=空格;鸣潮PC:空格或Shift(存疑) | G11: 闪避默认键+受身输入 | H11: S1,S3,S6 | I11: P0 | J11: S | K11: 1 | L11: 0 | M11: 1 | N11: 0 | O11: 1 | P11: =SUM(K11:O11) | Q11: 待评审
A12: 1.2.4 | B12: 1-输入与操控 | C12: 1.2 默认键位映射 | D12: 冲刺/疾跑 | E12: 鸣潮手机:冲刺与前进需分开 | F12: 荒野:Shift=冲刺 | G12: 明确前进+冲刺的键鼠实现 | H12: S3,S7 | I12: P0 | J12: S | K12: 1 | L12: 0 | M12: 2 | N12: 0 | O12: 1 | P12: =SUM(K12:O12) | Q12: 待评审
A13: 1.2.5 | B13: 1-输入与操控 | C13: 1.2 默认键位映射 | D13: 视角/锁定/部位锁定 | E13: 旅人:长按锁定键聚焦头/尾部位 | F13: 荒野:B=锁定;鸣潮PC:Tab切换目标 | G13: 鼠标控视角+锁定键+部位切换的键鼠表达 | H13: S1,S3,S6 | I13: P0 | J13: M | K13: 2 | L13: 0 | M13: 5 | N13: 0 | O13: 2 | P13: =SUM(K13:O13) | Q13: 待评审
A14: 1.2.6 | B14: 1-输入与操控 | C14: 1.2 默认键位映射 | D14: 建造/滑索/弹射 | E14: 旅人:制作键→选建造物 | F14: 荒野:钩锁=F;鸣潮PC:钩索=鼠标中键 | G14: 建造独立按键+快速选单 | H14: S1,S3,S6 | I14: P1 | J14: M | K14: 2 | L14: 1 | M14: 3 | N14: 0 | O14: 2 | P14: =SUM(K14:O14) | Q14: 待评审
A15: 1.2.7 | B15: 1-输入与操控 | C15: 1.2 默认键位映射 | D15: 奥义/大招 | E15: 旅人:每角色奥义(冷却) | F15: 鸣潮PC:R=共鸣解放 | G15: 奥义键独立化 | H15: S1,S6 | I15: P0 | J15: S | K15: 1 | L15: 0 | M15: 1 | N15: 0 | O15: 1 | P15: =SUM(K15:O15) | Q15: 待评审
A16: 1.2.8 | B16: 1-输入与操控 | C16: 1.2 默认键位映射 | D16: 使用道具/交互 | E16: 旅人:触屏按钮 | F16: 荒野:E道具、F采集;原神/星铁:F交互 | G16: 统一交互/采集/道具键位 | H16: S3,S14,S15 | I16: P0 | J16: S | K16: 1 | L16: 0 | M16: 1 | N16: 0 | O16: 1 | P16: =SUM(K16:O16) | Q16: 待评审
A17: 1.2.9 | B17: 1-输入与操控 | C17: 1.2 默认键位映射 | D17: 走/跑切换 | E17: 触屏摇杆推幅=走/跑 | F17: 原神:Ctrl切换走/跑 | G17: 键盘无模拟量,需走跑切换键 | H17: S14 | I17: P1 | J17: S | K17: 1 | L17: 0 | M17: 2 | N17: 0 | O17: 1 | P17: =SUM(K17:O17) | Q17: 待评审
A18: 1.2.10 | B18: 1-输入与操控 | C18: 1.2 默认键位映射 | D18: 武器/角色专属键位方案 | E18: 旅人:技能键随武器变化 | F18: 荒野:14武器按键语义重排(远程R2=射击、△=装填) | G18: 每把武器输出键鼠+手柄方案 | H18: S3,S1 | I18: P0 | J18: L | K18: =假设参数!$B$10*假设参数!$B$11 | L18: 0 | M18: 3 | N18: 0 | O18: =假设参数!$B$10*0.5 | P18: =SUM(K18:O18) | Q18: 待评审 | R18: 随武器数线性增长
A19: 1.3.1 | B19: 1-输入与操控 | C19: 1.3 键鼠交互差异 | D19: ESC返回栈 | E19: 触屏返回按钮 | F19: 荒野:Esc/H开始菜单、层层返回;星铁:ESC手机菜单 | G19: 关弹窗→关界面→呼出系统菜单,逐级回退 | H19: S3,S15 | I19: P0 | J19: M | K19: 2 | L19: 0 | M19: 5 | N19: 0 | O19: 3 | P19: =SUM(K19:O19) | Q19: 待评审
A20: 1.3.2 | B20: 1-输入与操控 | C20: 1.3 键鼠交互差异 | D20: 鼠标右键语义 | E20: - | F20: 荒野:右键=特殊攻击;鸣潮:右键=瞄准;星铁:右键=加速 | G20: 右键在战斗/菜单两种场景的分工 | H20: S3,S6,S15 | I20: P0 | J20: S | K20: 1 | L20: 0 | M20: 2 | N20: 0 | O20: 1 | P20: =SUM(K20:O20) | Q20: 待评审
A21: 1.3.3 | B21: 1-输入与操控 | C21: 1.3 键鼠交互差异 | D21: 滚轮语义 | E21: - | F21: 荒野:道具切换/地图缩放;鸣潮/星铁:视角远近 | G21: 滚轮复用规则与冲突规避 | H21: S3,S6,S15 | I21: P1 | J21: S | K21: 1 | L21: 0 | M21: 2 | N21: 0 | O21: 1 | P21: =SUM(K21:O21) | Q21: 待评审
A22: 1.3.4 | B22: 1-输入与操控 | C22: 1.3 键鼠交互差异 | D22: 长按 vs 点按 | E22: 触屏长按 | F22: 鸣潮:重击=长按普攻;荒野:集中模式按一次/长按 | G22: 长按类操作的键鼠等价与判定阈值 | H22: S6,S3 | I22: P0 | J22: M | K22: 1 | L22: 0 | M22: 3 | N22: 0 | O22: 2 | P22: =SUM(K22:O22) | Q22: 待评审
A23: 1.3.5 | B23: 1-输入与操控 | C23: 1.3 键鼠交互差异 | D23: 组合键表达 | E23: - | F23: 荒野:△+○=鼠标侧键1 | G23: 组合动作的组合键/侧键映射 | H23: S3 | I23: P1 | J23: M | K23: 2 | L23: 0 | M23: 3 | N23: 0 | O23: 2 | P23: =SUM(K23:O23) | Q23: 待评审
A24: 1.3.6 | B24: 1-输入与操控 | C24: 1.3 键鼠交互差异 | D24: 快捷栏/数字键 | E24: 触屏快捷轮盘 | F24: 荒野:F1~F8快捷盘、1~0/-/=栏位 | G24: 道具/建造/技能快捷栏的数字键体系 | H24: S3 | I24: P1 | J24: M | K24: 2 | L24: 3 | M24: 4 | N24: 0 | O24: 2 | P24: =SUM(K24:O24) | Q24: 待评审
A25: 1.3.7 | B25: 1-输入与操控 | C25: 1.3 键鼠交互差异 | D25: 界面内翻页/排序快捷键 | E25: 触屏点按 | F25: 荒野:Q/E翻页、G排序、X筛选、Tab切换显示 | G25: 统一全局界面快捷键规范 | H25: S3 | I25: P1 | J25: S | K25: 1 | L25: 0 | M25: 2 | N25: 0 | O25: 1 | P25: =SUM(K25:O25) | Q25: 待评审
A26: 1.3.8 | B26: 1-输入与操控 | C26: 1.3 键鼠交互差异 | D26: 聊天/社交快捷键 | E26: 触屏按钮 | F26: 荒野:Enter聊天、T语音、F9~F11贴图动作、L成员 | G26: 社交类快捷键 | H26: S3 | I26: P1 | J26: S | K26: 1 | L26: 0 | M26: 2 | N26: 0 | O26: 1 | P26: =SUM(K26:O26) | Q26: 待评审
A27: 1.3.9 | B27: 1-输入与操控 | C27: 1.3 键鼠交互差异 | D27: 鼠标光标模式(锁定/释放) | E27: 触屏无光标 | F27: 原神/星铁:探索战斗锁定光标控视角,按住左Alt临时唤出鼠标点UI | G27: 光标锁定/释放规则、Alt唤出、开界面自动释放 | H27: S13,S15 | I27: P0 | J27: M | K27: 2 | L27: 0 | M27: 4 | N27: 0 | O27: 2 | P27: =SUM(K27:O27) | Q27: 待评审 | R27: 之前清单遗漏的关键项
A28: 1.3.10 | B28: 1-输入与操控 | C28: 1.3 键鼠交互差异 | D28: 系统入口快捷键 | E28: 触屏主界面按钮 | F28: 星铁:C角色/B背包/M地图/J任务/F1~F5活动纪行跃迁指南商店 | G28: 各系统入口分配字母/F键 | H28: S15,S14 | I28: P1 | J28: S | K28: 2 | L28: 0 | M28: 2 | N28: 0 | O28: 1 | P28: =SUM(K28:O28) | Q28: 待评审
A29: 1.3.11 | B29: 1-输入与操控 | C29: 1.3 键鼠交互差异 | D29: 系统键冲突(Win/Alt+Tab/输入法) | E29: 无 | F29: Windows:Shift/Ctrl+Shift默认触发输入法切换;Win弹开始菜单 | G29: 游戏内禁用IME、可选屏蔽Win键、Alt+Tab失焦处理 | H29: S19 | I29: P0 | J29: M | K29: 1 | L29: 0 | M29: 4 | N29: 0 | O29: 3 | P29: =SUM(K29:O29) | Q29: 待评审 | R29: Shift作冲刺时必踩坑
A30: 1.3.12 | B30: 1-输入与操控 | C30: 1.3 键鼠交互差异 | D30: 鼠标原始输入与灵敏度曲线 | E30: 触屏滑动 | F30: 荒野/鸣潮:镜头灵敏度可调 | G30: Raw Input、关闭系统加速、X/Y分轴灵敏度 | H30: S6,EXP | I30: P1 | J30: M | K30: 1 | L30: 0 | M30: 4 | N30: 0 | O30: 2 | P30: =SUM(K30:O30) | Q30: 待评审
A31: 1.4.1 | B31: 1-输入与操控 | C31: 1.4 触屏手势→键鼠 | D31: 点按 | E31: 触屏点按 | F31: 左键/面键 | G31: 依赖1.1.6抽象层 | H31: EXP | I31: P0 | J31: S | K31: 0.5 | L31: 0 | M31: 0.5 | N31: 0 | O31: 0.5 | P31: =SUM(K31:O31) | Q31: 待评审
A32: 1.4.2 | B32: 1-输入与操控 | C32: 1.4 触屏手势→键鼠 | D32: 长按 | E32: 触屏长按 | F32: 荒野:长按=侧键2 | G32: 长按左键或独立键,可重映射 | H32: S3 | I32: P0 | J32: S | K32: 0.5 | L32: 0 | M32: 1 | N32: 0 | O32: 0.5 | P32: =SUM(K32:O32) | Q32: 待评审
A33: 1.4.3 | B33: 1-输入与操控 | C33: 1.4 触屏手势→键鼠 | D33: 滑屏转视角 | E33: 触屏滑动 | F33: 鼠标移动/右摇杆 | G33: 滑屏→鼠标/摇杆的灵敏度换算 | H33: S6 | I33: P0 | J33: M | K33: 1 | L33: 0 | M33: 3 | N33: 0 | O33: 1 | P33: =SUM(K33:O33) | Q33: 待评审
A34: 1.4.4 | B34: 1-输入与操控 | C34: 1.4 触屏手势→键鼠 | D34: 多点触控 | E34: 多指同时操作 | F34: 键鼠多指协同 | G34: 多键同按的输入缓冲 | H34: S7 | I34: P1 | J34: S | K34: 0.5 | L34: 0 | M34: 1 | N34: 0 | O34: 1 | P34: =SUM(K34:O34) | Q34: 待评审
A35: 1.4.5 | B35: 1-输入与操控 | C35: 1.4 触屏手势→键鼠 | D35: 双指缩放/旋转 | E35: 双指手势 | F35: 荒野:滚轮缩放、1/3旋转模型 | G35: 滚轮缩放+拖拽旋转 | H35: S3 | I35: P1 | J35: S | K35: 0.5 | L35: 0 | M35: 2 | N35: 0 | O35: 1 | P35: =SUM(K35:O35) | Q35: 待评审
A36: 1.4.6 | B36: 1-输入与操控 | C36: 1.4 触屏手势→键鼠 | D36: 虚拟摇杆幅度 | E36: 轻推走/推满跑 | F36: WASD开关式 | G36: WASD+走跑切换,手柄摇杆模拟量 | H36: EXP | I36: P0 | J36: S | K36: 0.5 | L36: 0 | M36: 1 | N36: 0 | O36: 0.5 | P36: =SUM(K36:O36) | Q36: 待评审
A37: 1.5.1 | B37: 1-输入与操控 | C37: 1.5 重映射与辅助 | D37: 键位自定义界面 | E37: 触屏布局自定义 | F37: 荒野/鸣潮/崛起PC:内置改键 | G37: 键鼠+手柄完整改键界面 | H37: S3,S6,S21 | I37: P0 | J37: L | K37: 3 | L37: 5 | M37: 10 | N37: 0 | O37: 4 | P37: =SUM(K37:O37) | Q37: 待评审
A38: 1.5.2 | B38: 1-输入与操控 | C38: 1.5 重映射与辅助 | D38: 灵敏度/震动 | E38: - | F38: 鸣潮:镜头灵敏度、震动力度 | G38: 鼠标灵敏度、摇杆死区、震动强度 | H38: S6 | I38: P1 | J38: S | K38: 1 | L38: 1 | M38: 2 | N38: 0 | O38: 1 | P38: =SUM(K38:O38) | Q38: 待评审
A39: 1.5.3 | B39: 1-输入与操控 | C39: 1.5 重映射与辅助 | D39: 辅助锁定 | E39: 鸣潮手机:自动锁定;旅人:长按锁定部位 | F39: - | G39: 自动/手动锁定开关、优先部位 | H39: S6,S1 | I39: P1 | J39: M | K39: 2 | L39: 0 | M39: 3 | N39: 0 | O39: 2 | P39: =SUM(K39:O39) | Q39: 待评审
A40: 1.5.4 | B40: 1-输入与操控 | C40: 1.5 重映射与辅助 | D40: 多设备配置独立保存 | E40: - | F40: 鸣潮:切设备后建议重校准 | G40: 每设备独立保存键位/灵敏度 | H40: S6 | I40: P1 | J40: S | K40: 1 | L40: 0 | M40: 2 | N40: 0 | O40: 1 | P40: =SUM(K40:O40) | Q40: 待评审
...

Sheet 参考来源
A1: 编号 | B1: 来源 | C1: 提取要点 | D1: 链接
A2: S1 | B2: Fami通TGS试玩报告(篝火转载) | C2: 旅人手机端:摇杆/技能连段/长按锁定部位/建造/状态栏就近 | D2: https://gouhuo.qq.com/content/detail/0_20250928163049_S1o9Vaz0N
A3: S2 | B3: 九游 旅人操作技巧 | C3: 点按轻击、长按重击 | D3: https://www.9game.cn/gwlrlr/11803558.html
A4: S3 | B4: 游侠网 荒野操作指南 | C4: 荒野键鼠/手柄全系统键位 | D4: https://gl.ali213.net/html/2025-2/1616997.html
A5: S4 | B5: 游民星空 荒野基本操作 | C5: 荒野手柄/键盘操作表 | D5: https://www.gamersky.com/handbook/202410/1836587.shtml
A6: S5 | B6: 游民星空 荒野画面优化 | C6: 荒野PC画质设置项 | D6: https://www.gamersky.com/handbook/202503/1896172.shtml
A7: S6 | B7: NTGame 鸣潮操作与设置 | C7: 鸣潮PC键鼠/手柄/触屏/设置建议 | D7: https://ntgame.com/wutheringwaves/controls/
A8: S7 | B8: 百度知道 电脑和手机玩鸣潮的区别 | C8: 端手操作与画质差异 | D8: https://zhidao.baidu.com/question/574515698126485364.html
A9: S8 | B9: 什么值得买 鸣潮画质对比 | C9: 端手画质差异 | D9: https://post.smzdm.com/zz/p/ako3z4l9/
A10: S9 | B10: 百度贴吧 鸣潮键鼠手柄热切换 | C10: 动设备自动切换界面 | D10: https://tieba.baidu.com/p/9025269279
A11: S10 | B11: B站 鸣潮显示设备切换 | C11: 多显示器/串流判定 | D11: https://www.bilibili.com/video/BV1riKh66EaU
A12: S11 | B12: NGA 鸣潮优化设置 | C12: NVIDIA Reflex隐藏选项 | D12: https://bbs.nga.cn/read.php?tid=46245547
... A24: S23 | B24: 什么值得买 荒野操作&画面设置 | C24: 低配降纹理、关泛光动态模糊 | D24: https://post.m.smzdm.com/zz/p/a447zrwl/
A25: EXP | B25: 行业经验 | C25: 无直接公开来源,需内部技术确认
